<?xml version="1.0" ?>
<!-- =================================================================================== -->
<!-- |    This document was autogenerated by xacro from Hexapoda.urdf.xacro            | -->
<!-- |    EDITING THIS FILE BY HAND IS NOT RECOMMENDED                                 | -->
<!-- =================================================================================== -->
<robot name="Hexapod">
  <gazebo reference="base_link">
    <material>Gazebo/Red</material>
  </gazebo>
  <gazebo reference="coxa_base_1">
    <material>Gazebo/Black</material>
  </gazebo>
  <gazebo reference="femur_base_1">
    <material>Gazebo/Black</material>
  </gazebo>
  <gazebo reference="tibia_base_1">
    <material>Gazebo/Black</material>
  </gazebo>
  <!-- 75mm taken cause 82mm was too outside of the base-->
  <link name="base_link">
    <inertial>
      <origin rpy="0.0 0.0 0.0" xyz="2.3553741432180777e-07 2.224092921723409e-05 0.003026303676307155"/>
      <mass value="0.7689223035628137"/>
      <inertia ixx="0.0010390137355587251" ixy="2.966445125900137e-10" ixz="-2.2246256263541832e-10" iyy="0.0010400150822437112" iyz="4.4983354420999026e-10" izz="0.0020742729104693478"/>
    </inertial>
    <visual>
      <origin rpy="0.0 0.0 0" xyz="0.0 0.0 0.0"/>
      <geometry>
        <!-- file:///$(find arm_03)/description/meshes/armA/armA_0.stl
                package://hexapod_rviz/meshes/Body.stl  -->
        <mesh filename="file:////home/waves/ros2_sim/install/hexapod/share/hexapod/models/hexagon.stl" scale="0.001 0.001 0.001"/>
      </geometry>
    </visual>
    <collision>
      <origin rpy="0.0 0.0 0" xyz="0.0 0.0 0.0"/>
      <geometry>
        <mesh filename="file:////home/waves/ros2_sim/install/hexapod/share/hexapod/models/hexagon.stl" scale="0.001 0.001 0.001"/>
      </geometry>
    </collision>
  </link>
  <link name="servo1_1">
    <visual>
      <origin rpy="0 0 0" xyz="0 0 0"/>
      <geometry>
        <box size="0.01 0.01 0.01"/>
      </geometry>
    </visual>
    <collision>
      <origin rpy="0 0 0" xyz="0 0 0"/>
      <geometry>
        <box size="0.01 0.01 0.01"/>
      </geometry>
    </collision>
    <inertial>
      <origin rpy="0.0 0.0 0.0" xyz="0 0 0"/>
      <mass value="0.07"/>
      <inertia ixx="1.1666666666666668e-06" ixy="0" ixz="0" iyy="1.1666666666666668e-06" iyz="0" izz="1.1666666666666668e-06"/>
    </inertial>
  </link>
  <joint name="servo_base_1" type="fixed">
    <parent link="base_link"/>
    <child link="servo1_1"/>
    <origin rpy="1.57 0 0.0" xyz="0.0 0.075 0.01"/>
  </joint>
  <link name="coxa_1">
    <visual>
      <origin rpy="0 0 0" xyz="0 0 -0.02"/>
      <geometry>
        <cylinder length="0.04" radius="0.005"/>
      </geometry>
    </visual>
    <collision>
      <origin rpy="0 0 0" xyz="0 0 -0.02"/>
      <geometry>
        <cylinder length="0.04" radius="0.005"/>
      </geometry>
    </collision>
    <inertial>
      <origin rpy="0 0 0" xyz="0 0 -0.02"/>
      <mass value="0.05"/>
      <inertia ixx="6.979166666666667e-06" ixy="0" ixz="0" iyy="6.979166666666667e-06" iyz="0" izz="6.25e-07"/>
    </inertial>
  </link>
  <joint name="coxa_base_1" type="revolute">
    <parent link="servo1_1"/>
    <child link="coxa_1"/>
    <!-- <origin xyz="${servo_length*d1} ${servo_length*d2} ${leg_radius*2}" rpy="1.57 ${pi * f} ${pi*ang}"/> -->
    <origin rpy="0 0.0 0.0" xyz="0.0 0.0 -0.005"/>
    <axis xyz="0 -1 0"/>
    <limit effort="100.0" lower="-0.7853981633974483" upper="0.7853981633974483" velocity="100.0"/>
  </joint>
  <link name="coxa_servo_1">
    <visual>
      <origin rpy="0 0 0" xyz="0 0 0"/>
      <geometry>
        <sphere radius="0.005"/>
      </geometry>
    </visual>
    <collision>
      <origin rpy="0 0 0" xyz="0 0 0"/>
      <geometry>
        <sphere radius="0.005"/>
      </geometry>
    </collision>
    <inertial>
      <origin rpy="0.0 0.0 0.0" xyz="0 0 0"/>
      <mass value="0.1"/>
      <inertia ixx="4.000000000000001e-06" ixy="0" ixz="0" iyy="4.000000000000001e-06" iyz="0" izz="4.000000000000001e-06"/>
    </inertial>
  </link>
  <joint name="coxa_servo_1" type="fixed">
    <parent link="coxa_1"/>
    <child link="coxa_servo_1"/>
    <origin rpy="0 0 0" xyz="0 0 -0.045"/>
  </joint>
  <link name="femur_1">
    <visual>
      <origin rpy="0 0 0" xyz="0 0 -0.0583"/>
      <geometry>
        <cylinder length="0.1166" radius="0.005"/>
      </geometry>
    </visual>
    <collision>
      <origin rpy="0 0 0" xyz="0 0 -0.0583"/>
      <geometry>
        <cylinder length="0.1166" radius="0.005"/>
      </geometry>
    </collision>
    <inertial>
      <origin rpy="0 0 0" xyz="0 0 -0.0583"/>
      <mass value="0.1"/>
      <inertia ixx="0.00011392133333333334" ixy="0" ixz="0" iyy="0.00011392133333333334" iyz="0" izz="1.25e-06"/>
    </inertial>
  </link>
  <joint name="femur_base_1" type="revolute">
    <parent link="coxa_servo_1"/>
    <child link="femur_1"/>
    <origin rpy="0.7853981633974483 0.0 0.0" xyz="0.0 0.0 -0.005"/>
    <axis xyz="-1 0 0"/>
    <limit effort="100.0" lower="-0.7853981633974483" upper="1.5707963267948966" velocity="100.0"/>
  </joint>
  <link name="femur_servo_1">
    <visual>
      <origin rpy="0 0 0" xyz="0 0 0"/>
      <geometry>
        <sphere radius="0.005"/>
      </geometry>
    </visual>
    <collision>
      <origin rpy="0 0 0" xyz="0 0 0"/>
      <geometry>
        <sphere radius="0.005"/>
      </geometry>
    </collision>
    <inertial>
      <origin rpy="0.0 0.0 0.0" xyz="0 0 0"/>
      <mass value="0.1"/>
      <inertia ixx="4.000000000000001e-06" ixy="0" ixz="0" iyy="4.000000000000001e-06" iyz="0" izz="4.000000000000001e-06"/>
    </inertial>
  </link>
  <joint name="femur_servo_1" type="fixed">
    <parent link="femur_1"/>
    <child link="femur_servo_1"/>
    <origin rpy="0 0 0" xyz="0 0 -0.1216"/>
  </joint>
  <link name="tibia_1">
    <visual>
      <origin rpy="0 0 0" xyz="0 0 -0.065"/>
      <geometry>
        <cylinder length="0.13" radius="0.005"/>
      </geometry>
    </visual>
    <collision>
      <origin rpy="0 0 0" xyz="0 0 -0.065"/>
      <geometry>
        <cylinder length="0.13" radius="0.005"/>
      </geometry>
    </collision>
    <inertial>
      <origin rpy="0 0 0" xyz="0 0 -0.065"/>
      <mass value="0.1"/>
      <inertia ixx="0.00014145833333333336" ixy="0" ixz="0" iyy="0.00014145833333333336" iyz="0" izz="1.25e-06"/>
    </inertial>
  </link>
  <joint name="tibia_base_1" type="revolute">
    <parent link="femur_servo_1"/>
    <child link="tibia_1"/>
    <origin rpy="-0.7853981633974483 0.0 0.0" xyz="0.0 0.0 -0.005"/>
    <axis xyz="-1 0 0"/>
    <limit effort="100.0" lower="-0.7853981633974483" upper="1.5707963267948966" velocity="100.0"/>
  </joint>
  <!-- <xacro:leg suffix="2" d1="-0.8661580944" d2="0.4997701026" ang="$(eval 1/3)" f="1"/>
    <xacro:leg suffix="3" d1="0.8661580944" d2="0.4997701026" ang="$(eval -1/3)" f="1"/>
    <xacro:leg suffix="4" d1="-0.8661580944" d2="-0.4997701026" ang="$(eval 2/3)" f="1"/>
    <xacro:leg suffix="5" d1="0.8661580944" d2="-0.4997701026" ang="$(eval -2/3)" f="1"/>
    <xacro:leg suffix="6" d1="0" d2="-1" ang="$(eval -1)" f="1"/> -->
</robot>
